Internal Server Error: /payment/
Traceback (most recent call last):
  File "/home/gairat/Desktop/programmin/High-load-Backend/Final/.venv/lib/python3.13/site-packages/kombu/utils/functional.py", line 32, in __call__
    return self.__value__
           ^^^^^^^^^^^^^^
AttributeError: 'ChannelPromise' object has no attribute '__value__'. Did you mean: '__call__'?

During handling of the above exception, another exception occurred:

Traceback (most recent call last):
  File "/home/gairat/Desktop/programmin/High-load-Backend/Final/.venv/lib/python3.13/site-packages/kombu/connection.py", line 472, in _reraise_as_library_errors
    yield
  File "/home/gairat/Desktop/programmin/High-load-Backend/Final/.venv/lib/python3.13/site-packages/kombu/connection.py", line 459, in _ensure_connection
    return retry_over_time(
        self._connection_factory, self.recoverable_connection_errors,
    ...<2 lines>...
        callback, timeout=timeout
    )
  File "/home/gairat/Desktop/programmin/High-load-Backend/Final/.venv/lib/python3.13/site-packages/kombu/utils/functional.py", line 318, in retry_over_time
    return fun(*args, **kwargs)
  File "/home/gairat/Desktop/programmin/High-load-Backend/Final/.venv/lib/python3.13/site-packages/kombu/connection.py", line 934, in _connection_factory
    self._connection = self._establish_connection()
                       ~~~~~~~~~~~~~~~~~~~~~~~~~~^^
  File "/home/gairat/Desktop/programmin/High-load-Backend/Final/.venv/lib/python3.13/site-packages/kombu/connection.py", line 860, in _establish_connection
    conn = self.transport.establish_connection()
  File "/home/gairat/Desktop/programmin/High-load-Backend/Final/.venv/lib/python3.13/site-packages/kombu/transport/pyamqp.py", line 203, in establish_connection
    conn.connect()
    ~~~~~~~~~~~~^^
  File "/home/gairat/Desktop/programmin/High-load-Backend/Final/.venv/lib/python3.13/site-packages/amqp/connection.py", line 324, in connect
    self.transport.connect()
    ~~~~~~~~~~~~~~~~~~~~~~^^
  File "/home/gairat/Desktop/programmin/High-load-Backend/Final/.venv/lib/python3.13/site-packages/amqp/transport.py", line 132, in connect
    self._connect(self.host, self.port, self.connect_timeout)
    ~~~~~~~~~~~~~^^^^^^^^^^^^^^^^^^^^^^^^^^^^^^^^^^^^^^^^^^^^
  File "/home/gairat/Desktop/programmin/High-load-Backend/Final/.venv/lib/python3.13/site-packages/amqp/transport.py", line 187, in _connect
    self.sock.connect(sa)
    ~~~~~~~~~~~~~~~~~^^^^
ConnectionRefusedError: [Errno 111] Connection refused

The above exception was the direct cause of the following exception:

Traceback (most recent call last):
  File "/home/gairat/Desktop/programmin/High-load-Backend/Final/.venv/lib/python3.13/site-packages/django/core/handlers/exception.py", line 55, in inner
    response = get_response(request)
  File "/home/gairat/Desktop/programmin/High-load-Backend/Final/.venv/lib/python3.13/site-packages/django/core/handlers/base.py", line 197, in _get_response
    response = wrapped_callback(request, *callback_args, **callback_kwargs)
  File "/home/gairat/Desktop/programmin/High-load-Backend/Final/.venv/lib/python3.13/site-packages/django/views/decorators/csrf.py", line 65, in _view_wrapper
    return view_func(request, *args, **kwargs)
  File "/home/gairat/Desktop/programmin/High-load-Backend/Final/.venv/lib/python3.13/site-packages/django/views/generic/base.py", line 104, in view
    return self.dispatch(request, *args, **kwargs)
           ~~~~~~~~~~~~~^^^^^^^^^^^^^^^^^^^^^^^^^^
  File "/home/gairat/Desktop/programmin/High-load-Backend/Final/.venv/lib/python3.13/site-packages/rest_framework/views.py", line 509, in dispatch
    response = self.handle_exception(exc)
  File "/home/gairat/Desktop/programmin/High-load-Backend/Final/.venv/lib/python3.13/site-packages/rest_framework/views.py", line 469, in handle_exception
    self.raise_uncaught_exception(exc)
    ~~~~~~~~~~~~~~~~~~~~~~~~~~~~~^^^^^
  File "/home/gairat/Desktop/programmin/High-load-Backend/Final/.venv/lib/python3.13/site-packages/rest_framework/views.py", line 480, in raise_uncaught_exception
    raise exc
  File "/home/gairat/Desktop/programmin/High-load-Backend/Final/.venv/lib/python3.13/site-packages/rest_framework/views.py", line 506, in dispatch
    response = handler(request, *args, **kwargs)
  File "/home/gairat/Desktop/programmin/High-load-Backend/Final/.venv/lib/python3.13/site-packages/rest_framework/decorators.py", line 50, in handler
    return func(*args, **kwargs)
  File "/home/gairat/Desktop/programmin/High-load-Backend/Final/ecommerce/store/views.py", line 271, in process_payment
    process_payment_task.delay(order_id, amount, payment_method)
    ~~~~~~~~~~~~~~~~~~~~~~~~~~^^^^^^^^^^^^^^^^^^^^^^^^^^^^^^^^^^
  File "/home/gairat/Desktop/programmin/High-load-Backend/Final/.venv/lib/python3.13/site-packages/celery/app/task.py", line 444, in delay
    return self.apply_async(args, kwargs)
           ~~~~~~~~~~~~~~~~^^^^^^^^^^^^^^
  File "/home/gairat/Desktop/programmin/High-load-Backend/Final/.venv/lib/python3.13/site-packages/celery/app/task.py", line 594, in apply_async
    return app.send_task(
           ~~~~~~~~~~~~~^
        self.name, args, kwargs, task_id=task_id, producer=producer,
        ^^^^^^^^^^^^^^^^^^^^^^^^^^^^^^^^^^^^^^^^^^^^^^^^^^^^^^^^^^^^
    ...<2 lines>...
        **options
        ^^^^^^^^^
    )
    ^
  File "/home/gairat/Desktop/programmin/High-load-Backend/Final/.venv/lib/python3.13/site-packages/celery/app/base.py", line 801, in send_task
    amqp.send_task_message(P, name, message, **options)
    ~~~~~~~~~~~~~~~~~~~~~~^^^^^^^^^^^^^^^^^^^^^^^^^^^^^
  File "/home/gairat/Desktop/programmin/High-load-Backend/Final/.venv/lib/python3.13/site-packages/celery/app/amqp.py", line 518, in send_task_message
    ret = producer.publish(
        body,
    ...<7 lines>...
        **properties
    )
  File "/home/gairat/Desktop/programmin/High-load-Backend/Final/.venv/lib/python3.13/site-packages/kombu/messaging.py", line 186, in publish
    return _publish(
        body, priority, content_type, content_encoding,
        headers, properties, routing_key, mandatory, immediate,
        exchange_name, declare, timeout
    )
  File "/home/gairat/Desktop/programmin/High-load-Backend/Final/.venv/lib/python3.13/site-packages/kombu/connection.py", line 556, in _ensured
    return fun(*args, **kwargs)
  File "/home/gairat/Desktop/programmin/High-load-Backend/Final/.venv/lib/python3.13/site-packages/kombu/messaging.py", line 195, in _publish
    channel = self.channel
              ^^^^^^^^^^^^
  File "/home/gairat/Desktop/programmin/High-load-Backend/Final/.venv/lib/python3.13/site-packages/kombu/messaging.py", line 218, in _get_channel
    channel = self._channel = channel()
                              ~~~~~~~^^
  File "/home/gairat/Desktop/programmin/High-load-Backend/Final/.venv/lib/python3.13/site-packages/kombu/utils/functional.py", line 34, in __call__
    value = self.__value__ = self.__contract__()
                             ~~~~~~~~~~~~~~~~~^^
  File "/home/gairat/Desktop/programmin/High-load-Backend/Final/.venv/lib/python3.13/site-packages/kombu/messaging.py", line 234, in <lambda>
    channel = ChannelPromise(lambda: connection.default_channel)
                                     ^^^^^^^^^^^^^^^^^^^^^^^^^^
  File "/home/gairat/Desktop/programmin/High-load-Backend/Final/.venv/lib/python3.13/site-packages/kombu/connection.py", line 953, in default_channel
    self._ensure_connection(**conn_opts)
    ~~~~~~~~~~~~~~~~~~~~~~~^^^^^^^^^^^^^
  File "/home/gairat/Desktop/programmin/High-load-Backend/Final/.venv/lib/python3.13/site-packages/kombu/connection.py", line 458, in _ensure_connection
    with ctx():
         ~~~^^
  File "/usr/lib64/python3.13/contextlib.py", line 162, in __exit__
    self.gen.throw(value)
    ~~~~~~~~~~~~~~^^^^^^^
  File "/home/gairat/Desktop/programmin/High-load-Backend/Final/.venv/lib/python3.13/site-packages/kombu/connection.py", line 476, in _reraise_as_library_errors
    raise ConnectionError(str(exc)) from exc
kombu.exceptions.OperationalError: [Errno 111] Connection refused
Internal Server Error: /payment/
Traceback (most recent call last):
  File "/home/gairat/Desktop/programmin/High-load-Backend/Final/.venv/lib/python3.13/site-packages/kombu/utils/functional.py", line 32, in __call__
    return self.__value__
           ^^^^^^^^^^^^^^
AttributeError: 'ChannelPromise' object has no attribute '__value__'. Did you mean: '__call__'?

During handling of the above exception, another exception occurred:

Traceback (most recent call last):
  File "/home/gairat/Desktop/programmin/High-load-Backend/Final/.venv/lib/python3.13/site-packages/kombu/connection.py", line 472, in _reraise_as_library_errors
    yield
  File "/home/gairat/Desktop/programmin/High-load-Backend/Final/.venv/lib/python3.13/site-packages/kombu/connection.py", line 459, in _ensure_connection
    return retry_over_time(
        self._connection_factory, self.recoverable_connection_errors,
    ...<2 lines>...
        callback, timeout=timeout
    )
  File "/home/gairat/Desktop/programmin/High-load-Backend/Final/.venv/lib/python3.13/site-packages/kombu/utils/functional.py", line 318, in retry_over_time
    return fun(*args, **kwargs)
  File "/home/gairat/Desktop/programmin/High-load-Backend/Final/.venv/lib/python3.13/site-packages/kombu/connection.py", line 934, in _connection_factory
    self._connection = self._establish_connection()
                       ~~~~~~~~~~~~~~~~~~~~~~~~~~^^
  File "/home/gairat/Desktop/programmin/High-load-Backend/Final/.venv/lib/python3.13/site-packages/kombu/connection.py", line 860, in _establish_connection
    conn = self.transport.establish_connection()
  File "/home/gairat/Desktop/programmin/High-load-Backend/Final/.venv/lib/python3.13/site-packages/kombu/transport/pyamqp.py", line 203, in establish_connection
    conn.connect()
    ~~~~~~~~~~~~^^
  File "/home/gairat/Desktop/programmin/High-load-Backend/Final/.venv/lib/python3.13/site-packages/amqp/connection.py", line 324, in connect
    self.transport.connect()
    ~~~~~~~~~~~~~~~~~~~~~~^^
  File "/home/gairat/Desktop/programmin/High-load-Backend/Final/.venv/lib/python3.13/site-packages/amqp/transport.py", line 132, in connect
    self._connect(self.host, self.port, self.connect_timeout)
    ~~~~~~~~~~~~~^^^^^^^^^^^^^^^^^^^^^^^^^^^^^^^^^^^^^^^^^^^^
  File "/home/gairat/Desktop/programmin/High-load-Backend/Final/.venv/lib/python3.13/site-packages/amqp/transport.py", line 187, in _connect
    self.sock.connect(sa)
    ~~~~~~~~~~~~~~~~~^^^^
ConnectionRefusedError: [Errno 111] Connection refused

The above exception was the direct cause of the following exception:

Traceback (most recent call last):
  File "/home/gairat/Desktop/programmin/High-load-Backend/Final/.venv/lib/python3.13/site-packages/django/core/handlers/exception.py", line 55, in inner
    response = get_response(request)
  File "/home/gairat/Desktop/programmin/High-load-Backend/Final/.venv/lib/python3.13/site-packages/django/core/handlers/base.py", line 197, in _get_response
    response = wrapped_callback(request, *callback_args, **callback_kwargs)
  File "/home/gairat/Desktop/programmin/High-load-Backend/Final/.venv/lib/python3.13/site-packages/django/views/decorators/csrf.py", line 65, in _view_wrapper
    return view_func(request, *args, **kwargs)
  File "/home/gairat/Desktop/programmin/High-load-Backend/Final/.venv/lib/python3.13/site-packages/django/views/generic/base.py", line 104, in view
    return self.dispatch(request, *args, **kwargs)
           ~~~~~~~~~~~~~^^^^^^^^^^^^^^^^^^^^^^^^^^
  File "/home/gairat/Desktop/programmin/High-load-Backend/Final/.venv/lib/python3.13/site-packages/rest_framework/views.py", line 509, in dispatch
    response = self.handle_exception(exc)
  File "/home/gairat/Desktop/programmin/High-load-Backend/Final/.venv/lib/python3.13/site-packages/rest_framework/views.py", line 469, in handle_exception
    self.raise_uncaught_exception(exc)
    ~~~~~~~~~~~~~~~~~~~~~~~~~~~~~^^^^^
  File "/home/gairat/Desktop/programmin/High-load-Backend/Final/.venv/lib/python3.13/site-packages/rest_framework/views.py", line 480, in raise_uncaught_exception
    raise exc
  File "/home/gairat/Desktop/programmin/High-load-Backend/Final/.venv/lib/python3.13/site-packages/rest_framework/views.py", line 506, in dispatch
    response = handler(request, *args, **kwargs)
  File "/home/gairat/Desktop/programmin/High-load-Backend/Final/.venv/lib/python3.13/site-packages/rest_framework/decorators.py", line 50, in handler
    return func(*args, **kwargs)
  File "/home/gairat/Desktop/programmin/High-load-Backend/Final/ecommerce/store/views.py", line 271, in process_payment
    process_payment_task.delay(order_id, amount, payment_method)
    ~~~~~~~~~~~~~~~~~~~~~~~~~~^^^^^^^^^^^^^^^^^^^^^^^^^^^^^^^^^^
  File "/home/gairat/Desktop/programmin/High-load-Backend/Final/.venv/lib/python3.13/site-packages/celery/app/task.py", line 444, in delay
    return self.apply_async(args, kwargs)
           ~~~~~~~~~~~~~~~~^^^^^^^^^^^^^^
  File "/home/gairat/Desktop/programmin/High-load-Backend/Final/.venv/lib/python3.13/site-packages/celery/app/task.py", line 594, in apply_async
    return app.send_task(
           ~~~~~~~~~~~~~^
        self.name, args, kwargs, task_id=task_id, producer=producer,
        ^^^^^^^^^^^^^^^^^^^^^^^^^^^^^^^^^^^^^^^^^^^^^^^^^^^^^^^^^^^^
    ...<2 lines>...
        **options
        ^^^^^^^^^
    )
    ^
  File "/home/gairat/Desktop/programmin/High-load-Backend/Final/.venv/lib/python3.13/site-packages/celery/app/base.py", line 801, in send_task
    amqp.send_task_message(P, name, message, **options)
    ~~~~~~~~~~~~~~~~~~~~~~^^^^^^^^^^^^^^^^^^^^^^^^^^^^^
  File "/home/gairat/Desktop/programmin/High-load-Backend/Final/.venv/lib/python3.13/site-packages/celery/app/amqp.py", line 518, in send_task_message
    ret = producer.publish(
        body,
    ...<7 lines>...
        **properties
    )
  File "/home/gairat/Desktop/programmin/High-load-Backend/Final/.venv/lib/python3.13/site-packages/kombu/messaging.py", line 186, in publish
    return _publish(
        body, priority, content_type, content_encoding,
        headers, properties, routing_key, mandatory, immediate,
        exchange_name, declare, timeout
    )
  File "/home/gairat/Desktop/programmin/High-load-Backend/Final/.venv/lib/python3.13/site-packages/kombu/connection.py", line 556, in _ensured
    return fun(*args, **kwargs)
  File "/home/gairat/Desktop/programmin/High-load-Backend/Final/.venv/lib/python3.13/site-packages/kombu/messaging.py", line 195, in _publish
    channel = self.channel
              ^^^^^^^^^^^^
  File "/home/gairat/Desktop/programmin/High-load-Backend/Final/.venv/lib/python3.13/site-packages/kombu/messaging.py", line 218, in _get_channel
    channel = self._channel = channel()
                              ~~~~~~~^^
  File "/home/gairat/Desktop/programmin/High-load-Backend/Final/.venv/lib/python3.13/site-packages/kombu/utils/functional.py", line 34, in __call__
    value = self.__value__ = self.__contract__()
                             ~~~~~~~~~~~~~~~~~^^
  File "/home/gairat/Desktop/programmin/High-load-Backend/Final/.venv/lib/python3.13/site-packages/kombu/messaging.py", line 234, in <lambda>
    channel = ChannelPromise(lambda: connection.default_channel)
                                     ^^^^^^^^^^^^^^^^^^^^^^^^^^
  File "/home/gairat/Desktop/programmin/High-load-Backend/Final/.venv/lib/python3.13/site-packages/kombu/connection.py", line 953, in default_channel
    self._ensure_connection(**conn_opts)
    ~~~~~~~~~~~~~~~~~~~~~~~^^^^^^^^^^^^^
  File "/home/gairat/Desktop/programmin/High-load-Backend/Final/.venv/lib/python3.13/site-packages/kombu/connection.py", line 458, in _ensure_connection
    with ctx():
         ~~~^^
  File "/usr/lib64/python3.13/contextlib.py", line 162, in __exit__
    self.gen.throw(value)
    ~~~~~~~~~~~~~~^^^^^^^
  File "/home/gairat/Desktop/programmin/High-load-Backend/Final/.venv/lib/python3.13/site-packages/kombu/connection.py", line 476, in _reraise_as_library_errors
    raise ConnectionError(str(exc)) from exc
kombu.exceptions.OperationalError: [Errno 111] Connection refused
